Workbook

Sheet macro_sam_2008_simp_3
B1: Act prim | C1: Act manu | D1: Act serv | E1: Prod prim | F1: Prod manu | G1: Prod serv | H1: Trabajo | I1: Capital | J1: Hogares | K1: Empresas | L1: Gobierno | M1: Cont_soc | N1: Pres_soc | O1: Imp_dir | P1: Imp_prod | Q1: Imptos_Espec | R1: IVA | S1: Arancel | T1: row | U1: S-I | V1: Var_Exis | W1: Total
A2: Act prim | B2: 0 | C2: 0 | D2: 0 | E2: 28.688309 | F2: 1.069724 | G2: 0.9415502 | H2: 0 | I2: 0 | J2: 0 | K2: 0 | L2: 0 | M2: 0 | N2: 0 | O2: 0 | P2: 0 | Q2: 0 | R2: 0 | S2: 0 | T2: 0 | U2: 0 | V2: 0 | W2: =+SUM(B2:V2) -> 30.699583 | X2: Vertical: Gasto | Y2: =+U2+V2 -> 0
A3: Act manu | B3: 0 | C3: 0 | D3: 0 | E3: 0.1735657 | F3: 61.503786 | G3: 1.3184261 | H3: 0 | I3: 0 | J3: 0 | K3: 0 | L3: 0 | M3: 0 | N3: 0 | O3: 0 | P3: 0 | Q3: 0 | R3: 0 | S3: 0 | T3: 0 | U3: 0 | V3: 0 | W3: =+SUM(B3:V3) -> 62.995777 | X3: Horizontal: Ingresos | Y3: =+U3+V3 -> 0
A4: Act serv | B4: 0 | C4: 0 | D4: 0 | E4: 0 | F4: 1.4954416 | G4: 84.471347 | H4: 0 | I4: 0 | J4: 0 | K4: 0 | L4: 0 | M4: 0 | N4: 0 | O4: 0 | P4: 0 | Q4: 0 | R4: 0 | S4: 0 | T4: 0 | U4: 0 | V4: 0 | W4: =+SUM(B4:V4) -> 85.966789 | Y4: =+U4+V4 -> 0
A5: Prod prim | B5: 3.1605376 | C5: 11.927984 | D5: 0.16408899 | E5: 0 | F5: 0 | G5: 0 | H5: 0 | I5: 0 | J5: 13.773547 | K5: 0 | L5: 0.017532974 | M5: 0 | N5: 0 | O5: 0 | P5: 0 | Q5: 0 | R5: 0 | S5: 0 | T5: 0 | U5: 0.16482158 | V5: 0 | W5: =+SUM(B5:V5) -> 29.208513 | Y5: =+U5+V5 -> 0.16482158
A6: Prod manu | B6: 6.9137748 | C6: 22.115421 | D6: 11.39659 | E6: 0 | F6: 0 | G6: 0 | H6: 0 | I6: 0 | J6: 8.4945262 | K6: 0 | L6: 0.083720262 | M6: 0 | N6: 0 | O6: 0 | P6: 0 | Q6: 0 | R6: 0 | S6: 0 | T6: 0 | U6: 20.612622 | V6: 0 | W6: =+SUM(B6:V6) -> 69.616654 | Y6: =+U6+V6 -> 20.612622
A7: Prod serv | B7: 4.4456911 | C7: 10.255334 | D7: 25.790392 | E7: 0 | F7: 0 | G7: 0 | H7: 0 | I7: 0 | J7: 34.326413 | K7: 0 | L7: 10.394112 | M7: 0 | N7: 0 | O7: 0 | P7: 0 | Q7: 0 | R7: 0 | S7: 0 | T7: 0 | U7: 3.5847821 | V7: 0 | W7: =+SUM(B7:V7) -> 88.796723 | Y7: =+U7+V7 -> 3.5847821
A8: Trabajo | B8: 2.9878269 | C8: 7.1010808 | D8: 24.044124 | E8: 0 | F8: 0 | G8: 0 | H8: 0 | I8: 0 | J8: 0 | K8: 0 | L8: 0 | M8: 0 | N8: 0 | O8: 0 | P8: 0 | Q8: 0 | R8: 0 | S8: 0 | T8: 0 | U8: 0 | V8: 0 | W8: =+SUM(B8:V8) -> 34.133031 | Y8: =+U8+V8 -> 0
A9: Capital | B9: 13.191753 | C9: 11.595958 | D9: 24.571594 | E9: 0 | F9: 0 | G9: 0 | H9: 0 | I9: 0 | J9: 0 | K9: 0 | L9: 0 | M9: 0 | N9: 0 | O9: 0 | P9: 0 | Q9: 0 | R9: 0 | S9: 0 | T9: 0 | U9: 0 | V9: 0 | W9: =+SUM(B9:V9) -> 49.359305 | Y9: =+U9+V9 -> 0
A10: Hogares | B10: 0 | C10: 0 | D10: 0 | E10: 0 | F10: 0 | G10: 0 | H10: 34.133031 | I10: 17.281502 | J10: 0 | K10: 17.431284 | L10: 2.1073795 | M10: 0 | N10: 3.1107667 | O10: 0 | P10: 0 | Q10: 0 | R10: 0 | S10: 0 | T10: 0 | U10: 0 | V10: 0 | W10: =+SUM(B10:V10) -> 74.063964 | Y10: =+U10+V10 -> 0
A11: Empresas | B11: 0 | C11: 0 | D11: 0 | E11: 0 | F11: 0 | G11: 0 | H11: 0 | I11: 31.096709 | J11: 0 | K11: 0 | L11: 0 | M11: 5.8570051 | N11: 0 | O11: 0 | P11: 0 | Q11: 0 | R11: 0 | S11: 0 | T11: 0 | U11: 0 | V11: 0 | W11: =+SUM(B11:V11) -> 36.953715 | Y11: =+U11+V11 -> 0
A12: Gobierno | B12: 0 | C12: 0 | D12: 0 | E12: 0 | F12: 0 | G12: 0 | H12: 0 | I12: 0.9810935 | J12: 0 | K12: 0 | L12: 0 | M12: 1.6238783 | N12: 0 | O12: 5.8828657 | P12: 0 | Q12: 0 | R12: 7.9597404 | S12: 0 | T12: 0 | U12: 0 | V12: 0 | W12: =+SUM(B12:V12) -> 16.447578 | Y12: =+U12+V12 -> 0
A13: Cont_soc | B13: 0 | C13: 0 | D13: 0 | E13: 0 | F13: 0 | G13: 0 | H13: 0 | I13: 0 | J13: 7.4808834 | K13: 0 | L13: 0 | M13: 0 | N13: 0 | O13: 0 | P13: 0 | Q13: 0 | R13: 0 | S13: 0 | T13: 0 | U13: 0 | V13: 0 | W13: =+SUM(B13:V13) -> 7.4808834 | Y13: =+U13+V13 -> 0
A14: Pres_soc | B14: 0 | C14: 0 | D14: 0 | E14: 0 | F14: 0 | G14: 0 | H14: 0 | I14: 0 | J14: 0 | K14: 1.5233916 | L14: 1.5873751 | M14: 0 | N14: 0 | O14: 0 | P14: 0 | Q14: 0 | R14: 0 | S14: 0 | T14: 0 | U14: 0 | V14: 0 | W14: =+SUM(B14:V14) -> 3.1107667 | Y14: =+U14+V14 -> 0
A15: Imp_dir | B15: 0 | C15: 0 | D15: 0 | E15: 0 | F15: 0 | G15: 0 | H15: 0 | I15: 0 | J15: 1.208967 | K15: 4.6738987 | L15: 0 | M15: 0 | N15: 0 | O15: 0 | P15: 0 | Q15: 0 | R15: 0 | S15: 0 | T15: 0 | U15: 0 | V15: 0 | W15: =+SUM(B15:V15) -> 5.8828657 | Y15: =+U15+V15 -> 0
... A22: Var_Exis | B22: 0 | C22: 0 | D22: 0 | E22: 0 | F22: 0 | G22: 0 | H22: 0 | I22: 0 | J22: 0 | K22: 0 | L22: 0 | M22: 0 | N22: 0 | O22: 0 | P22: 0 | Q22: 0 | R22: 0 | S22: 0 | T22: 0 | U22: 0 | V22: 0 | W22: =+SUM(B22:V22) -> 0 | Y22: =+U22+V22 -> 0
A23: Total | B23: =+SUM(B2:B22) -> 30.699583 | C23: =+SUM(C2:C22) -> 62.995777 | D23: =+SUM(D2:D22) -> 85.966789 | E23: =+SUM(E2:E22) -> 29.208513 | F23: =+SUM(F2:F22) -> 69.616654 | G23: =+SUM(G2:G22) -> 88.796723 | H23: =+SUM(H2:H22) -> 34.133031 | I23: =+SUM(I2:I22) -> 49.359305 | ... V23: =+SUM(V2:V22) -> 0 | W23: 0
B25: {=TRANSPOSE(W2:W22)} -> 30.699583 | C25: 62.995777 | D25: 85.966789 | E25: 29.208513 | F25: 69.616654 | G25: 88.796723 | H25: 34.133031 | I25: 49.359305 | J25: 74.063964 | K25: 36.953715 | L25: 16.447578 | M25: 7.4808834 | N25: 3.1107667 | O25: 5.8828657 | P25: 0 | Q25: 0 | R25: 7.9597404 | S25: 0 | T25: 0 | U25: 24.362226 | V25: 0
E26: =+E25-E23 -> 5.5300013e-09 | F26: =+F25-F23 -> 2.2299957e-09 | G26: =+G25-G23 -> 4.6860167e-07
B27: =ROUND(B23-B25,3) -> 0 | C27: =ROUND(C23-C25,3) -> 0 | D27: =ROUND(D23-D25,3) -> 0 | E27: =ROUND(E23-E25,3) -> 0 | F27: =ROUND(F23-F25,3) -> 0 | G27: =ROUND(G23-G25,3) -> 0 | H27: =ROUND(H23-H25,3) -> 0 | I27: =ROUND(I23-I25,3) -> 0 | ... V27: =ROUND(V23-V25,3) -> 0
B28: =+B23-B25 -> 3.9099994e-09 | C28: =+C23-C25 -> 2.2800037e-09 | D28: =+D23-D25 -> 8.300006e-09
B29: pasar las exportaciones al consumo de los hogares | H29: =+H20+H10 -> 34.133031 | I29: =+I20+I10 -> 17.281502 | J29: =+J21+T21 -> 8.7797731
B30: pasar los ingresos del capital y el trabajo row a los hogares | I30: =+I29-T9 -> 17.281502 | Q30: =+L10-P12-Q12 -> 2.1073795 | R30: =+R12+S12 -> 7.9597404 | S30: =+L10-S12 -> 2.1073795
B31: Quitar del consumo de los hogares lo que se importa | U31: =+U5+V5 -> 0.16482158
B32: pasar SI row a hogares | J32: -2.396 | U32: =+U6+V6 -> 20.612622
B33: qiotar ingresos del capital de row y de lo que el capital le transfiere a los hogares | U33: =+U7+V7 -> 3.5847821
J34: =+N10+J32 -> 0.71476672 | K34: =+L14+J32 -> -0.8086249
B35: pasar el arancel al IVA
B37: quitar el impuesto especifico a la actividad manufacturera y wal prod manu de esa actividad
B38: quitar ese monto al consumo de los hogares de prod manu
B39: quitar ese monto de los ingresos del gob y de las transferencias a los hogares
B41: El impuesto a los productos se elimina de cada producto, lo que se descuenta del consumo de los hogares, lo que a su vez se resta de las prestaciones sociales que recibe del gobierno
B43: =+J5+T5 -> 13.773547 | C43: =+B43-E20 -> 13.773547 | D43: =+C43-E19 -> 13.773547 | E43: =+D43-B16-B17 -> 13.773547 | I43: =+I10-T9 -> 17.281502
B44: =+J6+T6 -> 8.4945262 | C44: =+B44-F20 -> 8.4945262 | D44: =+C44-F19 -> 8.4945262 | E44: =+D44-C16-C17 -> 8.4945262
B45: =+J7+T7 -> 34.326413 | C45: =+B45-G20 -> 34.326413 | D45: =+C45-G19 -> 34.326413 | E45: =+D45-D16-D17 -> 34.326413
B47: =+H10+H20 -> 34.133031 | C47: =+I10+I20 -> 17.281502
E48: =+E18+E19 -> 0.34663777 | F48: =+F18+F19 -> 5.5477028 | G48: =+G18+G19 -> 2.0653998 | I48: =+L14-G48 -> -0.47802473
B49: =+J21+T21 -> 8.7797731
B51: =+B16+B17 -> 0 | C51: =+C16+C17 -> 0 | D51: =+D16+D17 -> 0
B53: =+macro_sam_2008_v1!B16 -> 0.10199653 | C53: =+macro_sam_2008_v1!C16 -> 0.24861445 | D53: =+macro_sam_2008_v1!D16 -> 1.0942427
...

Sheet macro_sam_2008__simp_1
B1: Act prim | C1: Act manu | D1: Act serv | E1: Prod prim | F1: Prod manu | G1: Prod serv | H1: Trabajo | I1: Capital | J1: Hogares | K1: Empresas | L1: Gobierno | M1: Cont_soc | N1: Pres_soc | O1: Imp_dir | P1: Imp_prod | Q1: Imptos_Espec | R1: IVA | S1: Arancel | T1: row | U1: S-I | V1: Var_Exis | W1: Total
A2: Act prim | B2: 0 | C2: 0 | D2: 0 | E2: 14.341871 | F2: 0 | G2: 0 | H2: 0 | I2: 0 | J2: 0 | K2: 0 | L2: 0 | M2: 0 | N2: 0 | O2: 0 | P2: 0 | Q2: 0 | R2: 0 | S2: 0 | T2: 0 | U2: 0 | V2: 0 | W2: =+SUM(B2:V2) -> 14.341871 | X2: Vertical: Gasto
A3: Act manu | B3: 0 | C3: 0 | D3: 0 | E3: 0 | F3: 19.770212 | G3: 0 | H3: 0 | I3: 0 | J3: 0 | K3: 0 | L3: 0 | M3: 0 | N3: 0 | O3: 0 | P3: 0 | Q3: 0 | R3: 0 | S3: 0 | T3: 0 | U3: 0 | V3: 0 | W3: =+SUM(B3:V3) -> 19.770212 | X3: Horizontal: Ingresos
A4: Act serv | B4: 0 | C4: 0 | D4: 0 | E4: 0 | F4: 0 | G4: 49.380253 | H4: 0 | I4: 0 | J4: 0 | K4: 0 | L4: 0 | M4: 0 | N4: 0 | O4: 0 | P4: 0 | Q4: 0 | R4: 0 | S4: 0 | T4: 0 | U4: 0 | V4: 0 | W4: =+SUM(B4:V4) -> 49.380253
A5: Prod prim | B5: 0 | C5: 0 | D5: 0 | E5: 0 | F5: 0 | G5: 0 | H5: 0 | I5: 0 | J5: 14.427016 | K5: 0 | L5: 0.017532974 | M5: 0 | N5: 0 | O5: 0 | P5: 0 | Q5: 0 | R5: 0 | S5: 0 | U5: 0.16482158 | W5: =+SUM(B5:V5) -> 14.609371 | Y5: =+T5+J5 -> 14.427016
A6: Prod manu | B6: 0 | C6: 0 | D6: 0 | E6: 0 | F6: 0 | G6: 0 | H6: 0 | I6: 0 | J6: 4.1279826 | K6: 0 | L6: 0.083720262 | M6: 0 | N6: 0 | O6: 0 | P6: 0 | Q6: 0 | R6: 0 | S6: 0 | U6: 20.612622 | W6: =+SUM(B6:V6) -> 24.824325 | Y6: =+T6+J6 -> 4.1279826
A7: Prod serv | B7: 0 | C7: 0 | D7: 0 | E7: 0 | F7: 0 | G7: 0 | H7: 0 | I7: 0 | J7: 37.466724 | K7: 0 | L7: 10.394112 | M7: 0 | N7: 0 | O7: 0 | P7: 0 | Q7: 0 | R7: 0 | S7: 0 | U7: 3.5847821 | W7: =+SUM(B7:V7) -> 51.445618 | Y7: =+T7+J7 -> 37.466724
A8: Trabajo | B8: 1.1501184 | C8: 8.1742547 | D8: 24.808658 | E8: 0 | F8: 0 | G8: 0 | H8: 0 | I8: 0 | J8: 0 | K8: 0 | L8: 0 | M8: 0 | N8: 0 | O8: 0 | P8: 0 | Q8: 0 | R8: 0 | S8: 0 | T8: 0 | U8: 0 | V8: 0 | W8: =+SUM(B8:V8) -> 34.133031
A9: Capital | B9: 13.191753 | C9: 11.595958 | D9: 24.571594 | E9: 0 | F9: 0 | G9: 0 | H9: 0 | I9: 0 | J9: 0 | K9: 0 | L9: 0 | M9: 0 | N9: 0 | O9: 0 | P9: 0 | Q9: 0 | R9: 0 | S9: 0 | U9: 0 | V9: 0 | W9: =+SUM(B9:V9) -> 49.359305
A10: Hogares | B10: 0 | C10: 0 | D10: 0 | E10: 0 | F10: 0 | G10: 0 | H10: 34.133031 | I10: 17.281502 | J10: 0 | K10: 17.431284 | L10: 0.55637804 | M10: 0 | N10: 4.0619131 | O10: 0 | P10: 0 | Q10: 0 | R10: 0 | S10: 0 | T10: 0 | U10: 0 | V10: 0 | W10: =+SUM(B10:V10) -> 73.464109
A11: Empresas | B11: 0 | C11: 0 | D11: 0 | E11: 0 | F11: 0 | G11: 0 | H11: 0 | I11: 31.096709 | J11: 0 | K11: 0 | L11: 0 | M11: 5.8570051 | N11: 0 | O11: 0 | P11: 0 | Q11: 0 | R11: 0 | S11: 0 | T11: 0 | U11: 0 | V11: 0 | W11: =+SUM(B11:V11) -> 36.953715
A12: Gobierno | B12: 0 | C12: 0 | D12: 0 | E12: 0 | F12: 0 | G12: 0 | H12: 0 | I12: 0.9810935 | J12: 0 | K12: 0 | L12: 0 | M12: 1.6238783 | N12: 0 | O12: 5.8828657 | R12: 7.3869769 | T12: 0 | U12: 0 | V12: 0 | W12: =+SUM(B12:V12) -> 15.874814
A13: Cont_soc | B13: 0 | C13: 0 | D13: 0 | E13: 0 | F13: 0 | G13: 0 | H13: 0 | I13: 0 | J13: 7.4808834 | K13: 0 | L13: 0 | M13: 0 | N13: 0 | O13: 0 | P13: 0 | Q13: 0 | R13: 0 | S13: 0 | T13: 0 | U13: 0 | V13: 0 | W13: =+SUM(B13:V13) -> 7.4808834
A14: Pres_soc | B14: 0 | C14: 0 | D14: 0 | E14: 0 | F14: 0 | G14: 0 | H14: 0 | I14: 0 | J14: 0 | K14: 1.5233916 | L14: 2.5385214 | M14: 0 | N14: 0 | O14: 0 | P14: 0 | Q14: 0 | R14: 0 | S14: 0 | T14: 0 | U14: 0 | V14: 0 | W14: =+SUM(B14:V14) -> 4.0619131
A15: Imp_dir | B15: 0 | C15: 0 | D15: 0 | E15: 0 | F15: 0 | G15: 0 | H15: 0 | I15: 0 | J15: 1.208967 | K15: 4.6738987 | L15: 0 | M15: 0 | N15: 0 | O15: 0 | P15: 0 | Q15: 0 | R15: 0 | S15: 0 | T15: 0 | U15: 0 | V15: 0 | W15: =+SUM(B15:V15) -> 5.8828657
A16: Imp_prod | E16: 0 | F16: 0 | G16: 0 | H16: 0 | I16: 0 | J16: 0 | K16: 0 | L16: 0 | M16: 0 | N16: 0 | O16: 0 | P16: 0 | Q16: 0 | R16: 0 | S16: 0 | T16: 0 | U16: 0 | V16: 0 | W16: =+SUM(B16:V16) -> 0
A17: Imptos_Espec | B17: 0 | D17: 0 | E17: 0 | F17: 0 | G17: 0 | H17: 0 | I17: 0 | J17: 0 | K17: 0 | L17: 0 | M17: 0 | N17: 0 | O17: 0 | P17: 0 | Q17: 0 | R17: 0 | S17: 0 | T17: 0 | U17: 0 | V17: 0 | W17: =+SUM(B17:V17) -> 0
A18: IVA | B18: 0 | C18: 0 | D18: 0 | E18: =(254765.8734+B29)/1000000 -> 0.26749956 | F18: =(5033784.004+C29)/1000000 -> 5.0541127 | G18: =(578585.5105+D29)/1000000 -> 2.0653647 | H18: 0 | I18: 0 | J18: 0 | K18: 0 | L18: 0 | M18: 0 | N18: 0 | O18: 0 | P18: 0 | Q18: 0 | R18: 0 | S18: 0 | T18: 0 | U18: 0 | V18: 0 | W18: =+SUM(B18:V18) -> 7.3869769
A19: Arancel | B19: 0 | C19: 0 | D19: 0 | H19: 0 | I19: 0 | J19: 0 | K19: 0 | L19: 0 | M19: 0 | N19: 0 | O19: 0 | P19: 0 | Q19: 0 | R19: 0 | S19: 0 | T19: 0 | U19: 0 | V19: 0 | W19: =+SUM(B19:V19) -> 0
A20: row | B20: 0 | C20: 0 | D20: 0 | J20: 0 | K20: 0 | L20: 0 | M20: 0 | N20: 0 | O20: 0 | P20: 0 | Q20: 0 | R20: 0 | S20: 0 | T20: 0 | U20: 0 | V20: 0 | W20: =+SUM(B20:V20) -> 0
A21: S-I | B21: 0 | C21: 0 | D21: 0 | E21: 0 | F21: 0 | G21: 0 | H21: 0 | I21: 0 | J21: 8.7797731 | K21: 13.32514 | L21: 2.257313 | M21: 0 | N21: 0 | O21: 0 | P21: 0 | Q21: 0 | R21: 0 | S21: 0 | U21: 0 | V21: 0 | W21: =+SUM(B21:V21) -> 24.362226
A22: Var_Exis | B22: 0 | C22: 0 | D22: 0 | E22: 0 | F22: 0 | G22: 0 | H22: 0 | I22: 0 | J22: 0 | K22: 0 | L22: 0 | M22: 0 | N22: 0 | O22: 0 | P22: 0 | Q22: 0 | R22: 0 | S22: 0 | T22: 0 | V22: 0 | W22: =+SUM(B22:V22) -> 0
A23: Total | B23: =+SUM(B2:B22) -> 14.341871 | C23: =+SUM(C2:C22) -> 19.770212 | D23: =+SUM(D2:D22) -> 49.380253 | E23: =+SUM(E2:E22) -> 14.609371 | F23: =+SUM(F2:F22) -> 24.824325 | G23: =+SUM(G2:G22) -> 51.445617 | H23: =+SUM(H2:H22) -> 34.133031 | I23: =+SUM(I2:I22) -> 49.359305 | ... V23: =+SUM(V2:V22) -> 0 | W23: 0
B25: {=TRANSPOSE(W2:W22)} -> 14.341871 | C25: 19.770212 | D25: 49.380253 | E25: 14.609371 | F25: 24.824325 | G25: 51.445618 | H25: 34.133031 | I25: 49.359305 | J25: 73.464109 | K25: 36.953715 | L25: 15.874814 | M25: 7.4808834 | N25: 4.0619131 | O25: 5.8828657 | P25: 0 | Q25: 0 | R25: 7.3869769 | S25: 0 | T25: 0 | U25: 24.362226 | V25: 0
B27: =ROUND(B23-B25,1) -> 0 | C27: =ROUND(C23-C25,1) -> 0 | D27: =ROUND(D23-D25,1) -> 0 | E27: =ROUND(E23-E25,1) -> 0 | F27: =ROUND(F23-F25,1) -> 0 | G27: =ROUND(G23-G25,1) -> 0 | H27: =ROUND(H23-H25,1) -> 0 | I27: =ROUND(I23-I25,1) -> 0 | ... V27: =ROUND(V23-V25,1) -> 0
A29: IVA | B29: 12733.687 | C29: 20328.661 | D29: 1486779.1
A31: Esta el la SAM que se está utilizando | N31: =+N10-E48 -> 4.0619131
N32: =+L14-E48 -> 2.5385214
B34: 1000000
B36: pasar las exportaciones al consumo de los hogares
B37: pasar los ingresos del capital y el trabajo row a los hogares
B38: Quitar del consumo de los hogares lo que se importa
B39: pasar SI row a hogares
B40: qiotar ingresos del capital de row y de lo que el capital le transfiere a los hogares
B42: quitar el arancel de los productos que consumen los hogares, quitarlo de los ingresos del gobierno y disminuir en ese monto las transferencias a los hogares
B44: quitar el impuesto especifico a la actividad manufacturera y wal prod manu de esa actividad
B45: quitar ese monto al consumo de los hogares de prod manu
B46: quitar ese monto de los ingresos del gob y de las transferencias a los hogares
B48: El impuesto a los productos se elimina de cada producto, lo que se descuenta del consumo de los hogares, lo que a su vez se resta de las prestaciones sociales que recibe del gobierno
B51: Act prim | C51: Act manu | D51: Act serv
...

Sheet macro_sam_2008__simp_2
B1: Act | C1: Prod | D1: Trabajo | E1: Capital | F1: Hogares | G1: Empresas | H1: Gobierno | I1: Cont_soc | J1: Pres_soc | K1: Imp_dir | L1: IVA | M1: S-I | N1: Total | O1: Vertical: Gasto
A2: Act | B2: 0 | C2: 83.492336 | D2: 0 | E2: 0 | F2: 0 | G2: 0 | H2: 0 | I2: 0 | J2: 0 | K2: 0 | L2: 0 | M2: 0 | N2: =+SUM(B2:M2) -> 83.492336 | O2: Horizontal: Ingresos | Q2: =+SUM(C2:C2) -> 83.492336
A3: Prod | B3: 0 | C3: 0 | D3: 0 | E3: 0 | F3: 56.021722 | G3: 0 | H3: 10.495365 | I3: 0 | J3: 0 | K3: 0 | L3: 0 | M3: 24.362226 | N3: =+SUM(B3:M3) -> 90.879314
A4: Trabajo | B4: 34.133031 | C4: 0 | D4: 0 | E4: 0 | F4: 0 | G4: 0 | H4: 0 | I4: 0 | J4: 0 | K4: 0 | L4: 0 | M4: 0 | N4: =+SUM(B4:M4) -> 34.133031 | Q4: =+SUM(B4:B4) -> 34.133031
A5: Capital | B5: 49.359305 | C5: 0 | D5: 0 | E5: 0 | F5: 0 | G5: 0 | H5: 0 | I5: 0 | J5: 0 | K5: 0 | L5: 0 | M5: 0 | N5: =+SUM(B5:M5) -> 49.359305 | Q5: =+SUM(B5:B5) -> 49.359305
A6: Hogares | B6: 0 | C6: 0 | D6: 34.133031 | E6: 17.281502 | F6: 0 | G6: 17.431284 | H6: 0.55637804 | I6: 0 | J6: =4.0619130575+0.0272368961616536 -> 4.08915 | K6: 0 | L6: 0 | M6: 0 | N6: =+SUM(B6:M6) -> 73.491346
A7: Empresas | B7: 0 | C7: 0 | D7: 0 | E7: 31.096709 | F7: 0 | G7: 0 | H7: 0 | I7: 5.8570051 | J7: 0 | K7: 0 | L7: 0 | M7: 0 | N7: =+SUM(B7:M7) -> 36.953715
A8: Gobierno | B8: 0 | C8: 0 | D8: 0 | E8: 0.9810935 | F8: 0 | G8: 0 | H8: 0 | I8: 1.6238783 | J8: 0 | K8: 5.8828657 | L8: 7.3869769 | M8: 0 | N8: =+SUM(B8:M8) -> 15.874814
A9: Cont_soc | B9: 0 | C9: 0 | D9: 0 | E9: 0 | F9: 7.4808834 | G9: 0 | H9: 0 | I9: 0 | J9: 0 | K9: 0 | L9: 0 | M9: 0 | N9: =+SUM(B9:M9) -> 7.4808834
A10: Pres_soc | B10: 0 | C10: 0 | D10: 0 | E10: 0 | F10: 0 | G10: 1.5233916 | H10: =2.5385214375+0.0272368961616536 -> 2.5657583 | I10: 0 | J10: 0 | K10: 0 | L10: 0 | M10: 0 | N10: =+SUM(B10:M10) -> 4.08915
A11: Imp_dir | B11: 0 | C11: 0 | D11: 0 | E11: 0 | F11: 1.208967 | G11: 4.6738987 | H11: 0 | I11: 0 | J11: 0 | K11: 0 | L11: 0 | M11: 0 | N11: =+SUM(B11:M11) -> 5.8828657
A12: IVA | B12: 0 | C12: 7.3869769 | D12: 0 | E12: 0 | F12: 0 | G12: 0 | H12: 0 | I12: 0 | J12: 0 | K12: 0 | L12: 0 | M12: 0 | N12: =+SUM(B12:M12) -> 7.3869769 | Q12: =+SUM(C12:C12) -> 7.3869769
A13: S-I | B13: 0 | C13: 0 | D13: 0 | E13: 0 | F13: 8.7797731 | G13: 13.32514 | H13: 2.257313 | I13: 0 | J13: 0 | K13: 0 | L13: 0 | M13: 0 | N13: =+SUM(B13:M13) -> 24.362226
A14: Total | B14: =+SUM(B2:B13) -> 83.492336 | C14: =+SUM(C2:C13) -> 90.879313 | D14: =+SUM(D2:D13) -> 34.133031 | E14: =+SUM(E2:E13) -> 49.359305 | F14: =+SUM(F2:F13) -> 73.491346 | G14: =+SUM(G2:G13) -> 36.953715 | H14: =+SUM(H2:H13) -> 15.874815 | I14: =+SUM(I2:I13) -> 7.4808834 | ... M14: =+SUM(M2:M13) -> 24.362226 | N14: 0
B16: {=TRANSPOSE(N2:N13)} -> 83.492336 | C16: 90.879314 | D16: 34.133031 | E16: 49.359305 | F16: 73.491346 | G16: 36.953715 | H16: 15.874814 | I16: 7.4808834 | J16: 4.08915 | K16: 5.8828657 | L16: 7.3869769 | M16: 24.362226
B17: =+B14-B16 -> 0 | C17: =+C14-C16 -> -4.7636166e-07 | D17: =+D14-D16 -> 7.4900228e-09 | E17: =+E14-E16 -> 3.000001e-08 | F17: =+F14-F16 -> 0 | G17: =+G14-G16 -> 0 | H17: =+H14-H16 -> 4.4039165e-07 | I17: =+I14-I16 -> 0 | ... M17: =+M14-M16 -> -1.6300064e-09
B18: =ROUND(B14-B16,1) -> 0 | C18: =ROUND(C14-C16,1) -> 0 | D18: =ROUND(D14-D16,1) -> 0 | E18: =ROUND(E14-E16,1) -> 0 | F18: =ROUND(F14-F16,1) -> 0 | G18: =ROUND(G14-G16,1) -> 0 | H18: =ROUND(H14-H16,1) -> 0 | I18: =ROUND(I14-I16,1) -> 0 | ... M18: =ROUND(M14-M16,1) -> 0
A20: IVA | B20: 12733.687 | F20: =+SUM(F3:F3) -> 56.021722 | H20: =+SUM(H3:H3) -> 10.495365 | M20: =+SUM(M3:M3) -> 24.362226
A22: Esta el la SAM que se está utilizando, con un solo producto producido en una sola actividad | J22: =+J6-C39 -> 4.08915
J23: =+H10-C39 -> 2.5657583
B25: 1000000 | F25: 0.027236896
B27: pasar las exportaciones al consumo de los hogares
B28: pasar los ingresos del capital y el trabajo row a los hogares
B29: Quitar del consumo de los hogares lo que se importa
B30: pasar SI row a hogares
B31: qiotar ingresos del capital de row y de lo que el capital le transfiere a los hogares
B33: quitar el arancel de los productos que consumen los hogares, quitarlo de los ingresos del gobierno y disminuir en ese monto las transferencias a los hogares
B35: quitar el impuesto especifico a la actividad manufacturera y wal prod manu de esa actividad
B36: quitar ese monto al consumo de los hogares de prod manu
B37: quitar ese monto de los ingresos del gob y de las transferencias a los hogares
B39: El impuesto a los productos se elimina de cada producto, lo que se descuenta del consumo de los hogares, lo que a su vez se resta de las prestaciones sociales que recibe del gobierno
B42: Act prim
A43: Prod prim | B43: 3.1605376 | D43: =+#REF!-B47 -> #REF! | F43: =+F3+D43 -> #REF!
A44: Prod manu | B44: 6.9137748 | D44: =+#REF!-#REF! -> #REF! | F44: =+#REF!+D44 -> #REF!
A45: Prod serv | B45: 4.4456911 | D45: =+#REF!-#REF! -> #REF! | F45: =+#REF!+D45 -> #REF!
B47: =+SUM(B43:B45) -> 14.520003
B49: Se elimina el gasto intermedio en productos, el que se asigna al prod principal de cada actvidad y se cuadra la diferencia con hogares
B51: Hacer que cada sector produzca un solo bien
B52: Prod prim
A53: Act prim | B53: 14.168306
...

Sheet macro_sam_2008__simp
B1: Act prim | C1: Act manu | D1: Act serv | E1: Prod prim | F1: Prod manu | G1: Prod serv | H1: Trabajo | I1: Capital | J1: Hogares | K1: Empresas | L1: Gobierno | M1: Cont_soc | N1: Pres_soc | O1: Imp_dir | P1: Imp_prod | Q1: Imptos_Espec | R1: IVA | S1: Arancel | T1: row | U1: S-I | V1: Var_Exis | W1: Total
A2: Act prim | B2: 0 | C2: 0 | D2: 0 | E2: 14.168306 | F2: 1.069724 | G2: 0.9415502 | H2: 0 | I2: 0 | J2: 0 | K2: 0 | L2: 0 | M2: 0 | N2: 0 | O2: 0 | P2: 0 | Q2: 0 | R2: 0 | S2: 0 | T2: 0 | U2: 0 | V2: 0 | W2: =+SUM(B2:V2) -> 16.17958 | X2: Vertical: Gasto
A3: Act manu | B3: 0 | C3: 0 | D3: 0 | E3: 0.1735657 | F3: 17.205047 | G3: 1.3184261 | H3: 0 | I3: 0 | J3: 0 | K3: 0 | L3: 0 | M3: 0 | N3: 0 | O3: 0 | P3: 0 | Q3: 0 | R3: 0 | S3: 0 | T3: 0 | U3: 0 | V3: 0 | W3: =+SUM(B3:V3) -> 18.697038 | X3: Horizontal: Ingresos
A4: Act serv | B4: 0 | C4: 0 | D4: 0 | E4: 0 | F4: 1.4954416 | G4: 47.120276 | H4: 0 | I4: 0 | J4: 0 | K4: 0 | L4: 0 | M4: 0 | N4: 0 | O4: 0 | P4: 0 | Q4: 0 | R4: 0 | S4: 0 | T4: 0 | U4: 0 | V4: 0 | W4: =+SUM(B4:V4) -> 48.615718
A5: Prod prim | E5: 0 | F5: 0 | G5: 0 | H5: 0 | I5: 0 | J5: 14.427016 | K5: 0 | L5: 0.017532974 | M5: 0 | N5: 0 | O5: 0 | P5: 0 | Q5: 0 | R5: 0 | S5: 0 | U5: 0.16482158 | W5: =+SUM(B5:V5) -> 14.609371 | Y5: =+T5+J5 -> 14.427016
A6: Prod manu | E6: 0 | F6: 0 | G6: 0 | H6: 0 | I6: 0 | J6: 4.1279826 | K6: 0 | L6: 0.083720262 | M6: 0 | N6: 0 | O6: 0 | P6: 0 | Q6: 0 | R6: 0 | S6: 0 | U6: 20.612622 | W6: =+SUM(B6:V6) -> 24.824325 | Y6: =+T6+J6 -> 4.1279826
A7: Prod serv | E7: 0 | F7: 0 | G7: 0 | H7: 0 | I7: 0 | J7: 37.466724 | K7: 0 | L7: 10.394112 | M7: 0 | N7: 0 | O7: 0 | P7: 0 | Q7: 0 | R7: 0 | S7: 0 | U7: 3.5847821 | W7: =+SUM(B7:V7) -> 51.445618 | Y7: =+T7+J7 -> 37.466724
A8: Trabajo | B8: 2.9878269 | C8: 7.1010808 | D8: 24.044124 | E8: 0 | F8: 0 | G8: 0 | H8: 0 | I8: 0 | J8: 0 | K8: 0 | L8: 0 | M8: 0 | N8: 0 | O8: 0 | P8: 0 | Q8: 0 | R8: 0 | S8: 0 | T8: 0 | U8: 0 | V8: 0 | W8: =+SUM(B8:V8) -> 34.133031
A9: Capital | B9: 13.191753 | C9: 11.595958 | D9: 24.571594 | E9: 0 | F9: 0 | G9: 0 | H9: 0 | I9: 0 | J9: 0 | K9: 0 | L9: 0 | M9: 0 | N9: 0 | O9: 0 | P9: 0 | Q9: 0 | R9: 0 | S9: 0 | U9: 0 | V9: 0 | W9: =+SUM(B9:V9) -> 49.359305
A10: Hogares | B10: 0 | C10: 0 | D10: 0 | E10: 0 | F10: 0 | G10: 0 | H10: 34.133031 | I10: 17.281502 | J10: 0 | K10: 17.431284 | L10: 0.55637804 | M10: 0 | N10: 4.0619131 | O10: 0 | P10: 0 | Q10: 0 | R10: 0 | S10: 0 | T10: 0 | U10: 0 | V10: 0 | W10: =+SUM(B10:V10) -> 73.464109
A11: Empresas | B11: 0 | C11: 0 | D11: 0 | E11: 0 | F11: 0 | G11: 0 | H11: 0 | I11: 31.096709 | J11: 0 | K11: 0 | L11: 0 | M11: 5.8570051 | N11: 0 | O11: 0 | P11: 0 | Q11: 0 | R11: 0 | S11: 0 | T11: 0 | U11: 0 | V11: 0 | W11: =+SUM(B11:V11) -> 36.953715
A12: Gobierno | B12: 0 | C12: 0 | D12: 0 | E12: 0 | F12: 0 | G12: 0 | H12: 0 | I12: 0.9810935 | J12: 0 | K12: 0 | L12: 0 | M12: 1.6238783 | N12: 0 | O12: 5.8828657 | R12: 7.3869769 | T12: 0 | U12: 0 | V12: 0 | W12: =+SUM(B12:V12) -> 15.874814
A13: Cont_soc | B13: 0 | C13: 0 | D13: 0 | E13: 0 | F13: 0 | G13: 0 | H13: 0 | I13: 0 | J13: 7.4808834 | K13: 0 | L13: 0 | M13: 0 | N13: 0 | O13: 0 | P13: 0 | Q13: 0 | R13: 0 | S13: 0 | T13: 0 | U13: 0 | V13: 0 | W13: =+SUM(B13:V13) -> 7.4808834
A14: Pres_soc | B14: 0 | C14: 0 | D14: 0 | E14: 0 | F14: 0 | G14: 0 | H14: 0 | I14: 0 | J14: 0 | K14: 1.5233916 | L14: 2.5385214 | M14: 0 | N14: 0 | O14: 0 | P14: 0 | Q14: 0 | R14: 0 | S14: 0 | T14: 0 | U14: 0 | V14: 0 | W14: =+SUM(B14:V14) -> 4.0619131
A15: Imp_dir | B15: 0 | C15: 0 | D15: 0 | E15: 0 | F15: 0 | G15: 0 | H15: 0 | I15: 0 | J15: 1.208967 | K15: 4.6738987 | L15: 0 | M15: 0 | N15: 0 | O15: 0 | P15: 0 | Q15: 0 | R15: 0 | S15: 0 | T15: 0 | U15: 0 | V15: 0 | W15: =+SUM(B15:V15) -> 5.8828657
A16: Imp_prod | E16: 0 | F16: 0 | G16: 0 | H16: 0 | I16: 0 | J16: 0 | K16: 0 | L16: 0 | M16: 0 | N16: 0 | O16: 0 | P16: 0 | Q16: 0 | R16: 0 | S16: 0 | T16: 0 | U16: 0 | V16: 0 | W16: =+SUM(B16:V16) -> 0
A17: Imptos_Espec | B17: 0 | D17: 0 | E17: 0 | F17: 0 | G17: 0 | H17: 0 | I17: 0 | J17: 0 | K17: 0 | L17: 0 | M17: 0 | N17: 0 | O17: 0 | P17: 0 | Q17: 0 | R17: 0 | S17: 0 | T17: 0 | U17: 0 | V17: 0 | W17: =+SUM(B17:V17) -> 0
A18: IVA | B18: 0 | C18: 0 | D18: 0 | E18: =(254765.8734+B29)/1000000 -> 0.26749956 | F18: =(5033784.004+C29)/1000000 -> 5.0541127 | G18: =(578585.5105+D29)/1000000 -> 2.0653647 | H18: 0 | I18: 0 | J18: 0 | K18: 0 | L18: 0 | M18: 0 | N18: 0 | O18: 0 | P18: 0 | Q18: 0 | R18: 0 | S18: 0 | T18: 0 | U18: 0 | V18: 0 | W18: =+SUM(B18:V18) -> 7.3869769
A19: Arancel | B19: 0 | C19: 0 | D19: 0 | H19: 0 | I19: 0 | J19: 0 | K19: 0 | L19: 0 | M19: 0 | N19: 0 | O19: 0 | P19: 0 | Q19: 0 | R19: 0 | S19: 0 | T19: 0 | U19: 0 | V19: 0 | W19: =+SUM(B19:V19) -> 0
A20: row | B20: 0 | C20: 0 | D20: 0 | J20: 0 | K20: 0 | L20: 0 | M20: 0 | N20: 0 | O20: 0 | P20: 0 | Q20: 0 | R20: 0 | S20: 0 | T20: 0 | U20: 0 | V20: 0 | W20: =+SUM(B20:V20) -> 0
A21: S-I | B21: 0 | C21: 0 | D21: 0 | E21: 0 | F21: 0 | G21: 0 | H21: 0 | I21: 0 | J21: 8.7797731 | K21: 13.32514 | L21: 2.257313 | M21: 0 | N21: 0 | O21: 0 | P21: 0 | Q21: 0 | R21: 0 | S21: 0 | U21: 0 | V21: 0 | W21: =+SUM(B21:V21) -> 24.362226
A22: Var_Exis | B22: 0 | C22: 0 | D22: 0 | E22: 0 | F22: 0 | G22: 0 | H22: 0 | I22: 0 | J22: 0 | K22: 0 | L22: 0 | M22: 0 | N22: 0 | O22: 0 | P22: 0 | Q22: 0 | R22: 0 | S22: 0 | T22: 0 | V22: 0 | W22: =+SUM(B22:V22) -> 0
A23: Total | B23: =+SUM(B2:B22) -> 16.17958 | C23: =+SUM(C2:C22) -> 18.697038 | D23: =+SUM(D2:D22) -> 48.615718 | E23: =+SUM(E2:E22) -> 14.609371 | F23: =+SUM(F2:F22) -> 24.824325 | G23: =+SUM(G2:G22) -> 51.445617 | H23: =+SUM(H2:H22) -> 34.133031 | I23: =+SUM(I2:I22) -> 49.359305 | ... V23: =+SUM(V2:V22) -> 0 | W23: 0
B25: {=TRANSPOSE(W2:W22)} -> 16.17958 | C25: 18.697038 | D25: 48.615718 | E25: 14.609371 | F25: 24.824325 | G25: 51.445618 | H25: 34.133031 | I25: 49.359305 | J25: 73.464109 | K25: 36.953715 | L25: 15.874814 | M25: 7.4808834 | N25: 4.0619131 | O25: 5.8828657 | P25: 0 | Q25: 0 | R25: 7.3869769 | S25: 0 | T25: 0 | U25: 24.362226 | V25: 0
B27: =ROUND(B23-B25,1) -> 0 | C27: =ROUND(C23-C25,1) -> 0 | D27: =ROUND(D23-D25,1) -> 0 | E27: =ROUND(E23-E25,1) -> 0 | F27: =ROUND(F23-F25,1) -> 0 | G27: =ROUND(G23-G25,1) -> 0 | H27: =ROUND(H23-H25,1) -> 0 | I27: =ROUND(I23-I25,1) -> 0 | ... V27: =ROUND(V23-V25,1) -> 0
A29: IVA | B29: 12733.687 | C29: 20328.661 | D29: 1486779.1
A31: Esta el la SAM que se está utilizando | N31: =+N10-E48 -> 4.0619131
N32: =+L14-E48 -> 2.5385214
B34: 1000000
B36: pasar las exportaciones al consumo de los hogares
B37: pasar los ingresos del capital y el trabajo row a los hogares
B38: Quitar del consumo de los hogares lo que se importa
B39: pasar SI row a hogares
B40: qiotar ingresos del capital de row y de lo que el capital le transfiere a los hogares
B42: quitar el arancel de los productos que consumen los hogares, quitarlo de los ingresos del gobierno y disminuir en ese monto las transferencias a los hogares
B44: quitar el impuesto especifico a la actividad manufacturera y wal prod manu de esa actividad
B45: quitar ese monto al consumo de los hogares de prod manu
B46: quitar ese monto de los ingresos del gob y de las transferencias a los hogares
B48: El impuesto a los productos se elimina de cada producto, lo que se descuenta del consumo de los hogares, lo que a su vez se resta de las prestaciones sociales que recibe del gobierno
B51: Act prim | C51: Act manu | D51: Act serv
...

Sheet macro_sam_2008_v1
B1: Act prim | C1: Act manu | D1: Act serv | E1: Prod prim | F1: Prod manu | G1: Prod serv | H1: Trabajo | I1: Capital | J1: Hogares | K1: Empresas | L1: Gobierno | M1: Cont_soc | N1: Pres_soc | O1: Imp_dir | P1: Imp_prod | Q1: Imptos_Espec | R1: IVA | S1: Arancel | T1: row | U1: S-I | V1: Var_Exis | W1: Total
A2: Act prim | B2: 0 | C2: 0 | D2: 0 | E2: =(28803039.28-B29)/1000000 -> 28.790306 | F2: 1.069724 | G2: 0.9415502 | H2: 0 | I2: 0 | J2: 0 | K2: 0 | L2: 0 | M2: 0 | N2: 0 | O2: 0 | P2: 0 | Q2: 0 | R2: 0 | S2: 0 | T2: 0 | U2: 0 | V2: 0 | W2: =+SUM(B2:V2) -> 30.80158 | X2: Vertical: Gasto
A3: Act manu | B3: 0 | C3: 0 | D3: 0 | E3: 0.1735657 | F3: =(62723730.2-C29)/1000000 -> 62.703402 | G3: 1.3184261 | H3: 0 | I3: 0 | J3: 0 | K3: 0 | L3: 0 | M3: 0 | N3: 0 | O3: 0 | P3: 0 | Q3: 0 | R3: 0 | S3: 0 | T3: 0 | U3: 0 | V3: 0 | W3: =+SUM(B3:V3) -> 64.195393 | X3: Horizontal: Ingresos
A4: Act serv | B4: 0 | C4: 0 | D4: 0 | E4: 0 | F4: 1.4954416 | G4: =(87052368.69-D29)/1000000 -> 85.56559 | H4: 0 | I4: 0 | J4: 0 | K4: 0 | L4: 0 | M4: 0 | N4: 0 | O4: 0 | P4: 0 | Q4: 0 | R4: 0 | S4: 0 | T4: 0 | U4: 0 | V4: 0 | W4: =+SUM(B4:V4) -> 87.061031
A5: Prod prim | B5: 3.1605376 | C5: 11.927984 | D5: 0.16408899 | E5: 0 | F5: 0 | G5: 0 | H5: 0 | I5: 0 | J5: 1.2115916 | K5: 0 | L5: 0.017532974 | M5: 0 | N5: 0 | O5: 0 | P5: 0 | Q5: 0 | R5: 0 | S5: 0 | T5: 18.405805 | U5: 0.25796459 | V5: -0.093143005 | W5: =+SUM(B5:V5) -> 35.052362 | Y5: =+U5/U23+V5/U23 -> 0.0067654566 | Z5: =+(U5+V5)/$U$23 -> 0.0067654566
A6: Prod manu | B6: 6.9137748 | C6: 22.115421 | D6: 11.39659 | E6: 0 | F6: 0 | G6: 0 | H6: 0 | I6: 0 | J6: 23.089911 | K6: 0 | L6: 0.083720262 | M6: 0 | N6: 0 | O6: 0 | P6: 0 | Q6: 0 | R6: 0 | S6: 0 | T6: 13.489883 | U6: 19.344119 | V6: 1.2685029 | W6: =+SUM(B6:V6) -> 97.701922 | Z6: =+(U6+V6)/$U$23 -> 0.84608945
A7: Prod serv | B7: 4.4456911 | C7: 10.255334 | D7: 25.790392 | E7: 0 | F7: 0 | G7: 0 | H7: 0 | I7: 0 | J7: 32.838168 | K7: 0 | L7: 10.394112 | M7: 0 | N7: 0 | O7: 0 | P7: 0 | Q7: 0 | R7: 0 | S7: 0 | T7: 7.0574766 | U7: 3.5766315 | V7: 0.0081506483 | W7: =+SUM(B7:V7) -> 94.365956 | Z7: =+(U7+V7)/$U$23 -> 0.1471451
A8: Trabajo | B8: 2.9878269 | C8: 7.1010808 | D8: 24.044124 | E8: 0 | F8: 0 | G8: 0 | H8: 0 | I8: 0 | J8: 0 | K8: 0 | L8: 0 | M8: 0 | N8: 0 | O8: 0 | P8: 0 | Q8: 0 | R8: 0 | S8: 0 | T8: 0 | U8: 0 | V8: 0 | W8: =+SUM(B8:V8) -> 34.133031 | Y8: =+B8/(B8+B9) -> 0.18466653 | Z8: =+C8/(C8+C9) -> 0.37979709 | AA8: =+D8/(D8+D9) -> 0.4945751
A9: Capital | B9: 13.191753 | C9: 11.595958 | D9: 24.571594 | E9: 0 | F9: 0 | G9: 0 | H9: 0 | I9: 0 | J9: 0 | K9: 0 | L9: 0 | M9: 0 | N9: 0 | O9: 0 | P9: 0 | Q9: 0 | R9: 0 | S9: 0 | T9: 4.7540542 | U9: 0 | V9: 0 | W9: =+SUM(B9:V9) -> 54.113359 | Y9: =1-Y8 -> 0.81533347 | Z9: =1-Z8 -> 0.62020291 | AA9: =1-AA8 -> 0.5054249
A10: Hogares | B10: 0 | C10: 0 | D10: 0 | E10: 0 | F10: 0 | G10: 0 | H10: 34.131359 | I10: 12.060736 | J10: 0 | K10: 17.431284 | L10: 2.1073795 | M10: 0 | N10: 5.5067667 | O10: 0 | P10: 0 | Q10: 0 | R10: 0 | S10: 0 | T10: 0 | U10: 0 | V10: 0 | W10: =+SUM(B10:V10) -> 71.237526
A11: Empresas | B11: 0 | C11: 0 | D11: 0 | E11: 0 | F11: 0 | G11: 0 | H11: 0 | I11: 31.096709 | J11: 0 | K11: 0 | L11: 0 | M11: 5.8570051 | N11: 0 | O11: 0 | P11: 0 | Q11: 0 | R11: 0 | S11: 0 | T11: 0 | U11: 0 | V11: 0 | W11: =+SUM(B11:V11) -> 36.953715
A12: Gobierno | B12: 0 | C12: 0 | D12: 0 | E12: 0 | F12: 0 | G12: 0 | H12: 0 | I12: 0.9810935 | J12: 0 | K12: 0 | L12: 0 | M12: 1.6238783 | N12: 0 | O12: 5.8828657 | P12: 1.4448537 | Q12: 0.9510015 | R12: 7.3869769 | S12: 0.57276354 | T12: 0 | U12: 0 | V12: 0 | W12: =+SUM(B12:V12) -> 18.843433
A13: Cont_soc | B13: 0 | C13: 0 | D13: 0 | E13: 0 | F13: 0 | G13: 0 | H13: 0 | I13: 0 | J13: 7.4808834 | K13: 0 | L13: 0 | M13: 0 | N13: 0 | O13: 0 | P13: 0 | Q13: 0 | R13: 0 | S13: 0 | T13: 0 | U13: 0 | V13: 0 | W13: =+SUM(B13:V13) -> 7.4808834
A14: Pres_soc | B14: 0 | C14: 0 | D14: 0 | E14: 0 | F14: 0 | G14: 0 | H14: 0 | I14: 0 | J14: 0 | K14: 1.5233916 | L14: 3.9833751 | M14: 0 | N14: 0 | O14: 0 | P14: 0 | Q14: 0 | R14: 0 | S14: 0 | T14: 0 | U14: 0 | V14: 0 | W14: =+SUM(B14:V14) -> 5.5067667
A15: Imp_dir | B15: 0 | C15: 0 | D15: 0 | E15: 0 | F15: 0 | G15: 0 | H15: 0 | I15: 0 | J15: 1.208967 | K15: 4.6738987 | L15: 0 | M15: 0 | N15: 0 | O15: 0 | P15: 0 | Q15: 0 | R15: 0 | S15: 0 | T15: 0 | U15: 0 | V15: 0 | W15: =+SUM(B15:V15) -> 5.8828657
A16: Imp_prod | B16: 0.10199653 | C16: 0.24861445 | D16: 1.0942427 | E16: 0 | F16: 0 | G16: 0 | H16: 0 | I16: 0 | J16: 0 | K16: 0 | L16: 0 | M16: 0 | N16: 0 | O16: 0 | P16: 0 | Q16: 0 | R16: 0 | S16: 0 | T16: 0 | U16: 0 | V16: 0 | W16: =+SUM(B16:V16) -> 1.4448537
A17: Imptos_Espec | B17: 0 | C17: 0.9510015 | D17: 0 | E17: 0 | F17: 0 | G17: 0 | H17: 0 | I17: 0 | J17: 0 | K17: 0 | L17: 0 | M17: 0 | N17: 0 | O17: 0 | P17: 0 | Q17: 0 | R17: 0 | S17: 0 | T17: 0 | U17: 0 | V17: 0 | W17: =+SUM(B17:V17) -> 0.9510015
A18: IVA | B18: 0 | C18: 0 | D18: 0 | E18: =(254765.8734+B29)/1000000 -> 0.26749956 | F18: =(5033784.004+C29)/1000000 -> 5.0541127 | G18: =(578585.5105+D29)/1000000 -> 2.0653647 | H18: 0 | I18: 0 | J18: 0 | K18: 0 | L18: 0 | M18: 0 | N18: 0 | O18: 0 | P18: 0 | Q18: 0 | R18: 0 | S18: 0 | T18: 0 | U18: 0 | V18: 0 | W18: =+SUM(B18:V18) -> 7.3869769
A19: Arancel | B19: 0 | C19: 0 | D19: 0 | E19: 0.079138214 | F19: 0.49359016 | G19: 3.5171018e-05 | H19: 0 | I19: 0 | J19: 0 | K19: 0 | L19: 0 | M19: 0 | N19: 0 | O19: 0 | P19: 0 | Q19: 0 | R19: 0 | S19: 0 | T19: 0 | U19: 0 | V19: 0 | W19: =+SUM(B19:V19) -> 0.57276354
A20: row | B20: 0 | C20: 0 | D20: 0 | E20: 5.7418532 | F20: 26.885652 | G20: 4.4749894 | H20: 0.00167188 | I20: 9.9748206 | J20: 0 | K20: 0 | L20: 0 | M20: 0 | N20: 0 | O20: 0 | P20: 0 | Q20: 0 | R20: 0 | S20: 0 | T20: 0 | U20: 0 | V20: 0 | W20: =+SUM(B20:V20) -> 47.078987
A21: S-I | B21: 0 | C21: 0 | D21: 0 | E21: 0 | F21: 0 | G21: 0 | H21: 0 | I21: 0 | J21: 5.4080054 | K21: 13.32514 | L21: 2.257313 | M21: 0 | N21: 0 | O21: 0 | P21: 0 | Q21: 0 | R21: 0 | S21: 0 | T21: 3.3717677 | U21: 0 | V21: 0 | W21: =+SUM(B21:V21) -> 24.362226
A22: Var_Exis | B22: 0 | C22: 0 | D22: 0 | E22: 0 | F22: 0 | G22: 0 | H22: 0 | I22: 0 | J22: 0 | K22: 0 | L22: 0 | M22: 0 | N22: 0 | O22: 0 | P22: 0 | Q22: 0 | R22: 0 | S22: 0 | T22: 0 | U22: 1.1835105 | V22: 0 | W22: =+SUM(B22:V22) -> 1.1835105
A23: Total | B23: =+SUM(B2:B22) -> 30.80158 | C23: =+SUM(C2:C22) -> 64.195393 | D23: =+SUM(D2:D22) -> 87.061031 | E23: =+SUM(E2:E22) -> 35.052362 | F23: =+SUM(F2:F22) -> 97.701922 | G23: =+SUM(G2:G22) -> 94.365955 | H23: =+SUM(H2:H22) -> 34.133031 | I23: =+SUM(I2:I22) -> 54.113359 | ... V23: =+SUM(V2:V22) -> 1.1835105 | W23: 0
B25: {=TRANSPOSE(W2:W22)} -> 30.80158 | C25: 64.195393 | D25: 87.061031 | E25: 35.052362 | F25: 97.701922 | G25: 94.365956 | H25: 34.133031 | I25: 54.113359 | J25: 71.237526 | K25: 36.953715 | L25: 18.843433 | M25: 7.4808834 | N25: 5.5067667 | O25: 5.8828657 | P25: 1.4448537 | Q25: 0.9510015 | R25: 7.3869769 | S25: 0.57276354 | T25: 47.078987 | U25: 24.362226 | V25: 1.1835105
B27: =ROUND(B23-B25,1) -> 0 | C27: =ROUND(C23-C25,1) -> 0 | D27: =ROUND(D23-D25,1) -> 0 | E27: =ROUND(E23-E25,1) -> 0 | F27: =ROUND(F23-F25,1) -> 0 | G27: =ROUND(G23-G25,1) -> 0 | H27: =ROUND(H23-H25,1) -> 0 | I27: =ROUND(I23-I25,1) -> 0 | ... V27: =ROUND(V23-V25,1) -> 0
A29: IVA | B29: 12733.687 | C29: 20328.661 | D29: 1486779.1
K30: =+K15/I11 -> 0.15030203
A31: Esta el la base de las SAMs que se están utilizando
B34: 1000000
B39: La producción no tiene IVA

Sheet macro_sam_2008
B1: Act prim | C1: Act manu | D1: Act serv | E1: Prod prim | F1: Prod manu | G1: Prod serv | H1: Trabajo | I1: Capital | J1: Hogares | K1: Empresas | L1: Gobierno | M1: Cont_soc | N1: Pres_soc | O1: Imp_dir | P1: Imp_prod | Q1: Imptos_Espec | R1: IVA | S1: Arancel | T1: row | U1: S-I | V1: Var_Exis | W1: Total
A2: Act prim | B2: 0 | C2: 0 | D2: 0 | E2: 28.803039 | F2: 1.069724 | G2: 0.9415502 | H2: 0 | I2: 0 | J2: 0 | K2: 0 | L2: 0 | M2: 0 | N2: 0 | O2: 0 | P2: 0 | Q2: 0 | R2: 0 | S2: 0 | T2: 0 | U2: 0 | V2: 0 | W2: =+SUM(B2:V2) -> 30.814314 | X2: Vertical: Gasto
A3: Act manu | B3: 0 | C3: 0 | D3: 0 | E3: 0.1735657 | F3: 62.72373 | G3: 1.3184261 | H3: 0 | I3: 0 | J3: 0 | K3: 0 | L3: 0 | M3: 0 | N3: 0 | O3: 0 | P3: 0 | Q3: 0 | R3: 0 | S3: 0 | T3: 0 | U3: 0 | V3: 0 | W3: =+SUM(B3:V3) -> 64.215722 | X3: Horizontal: Ingresos
A4: Act serv | B4: 0 | C4: 0 | D4: 0 | E4: 0 | F4: 1.4954416 | G4: 87.052369 | H4: 0 | I4: 0 | J4: 0 | K4: 0 | L4: 0 | M4: 0 | N4: 0 | O4: 0 | P4: 0 | Q4: 0 | R4: 0 | S4: 0 | T4: 0 | U4: 0 | V4: 0 | W4: =+SUM(B4:V4) -> 88.54781
A5: Prod prim | B5: 3.1605376 | C5: 11.927984 | D5: 0.16408899 | E5: 0 | F5: 0 | G5: 0 | H5: 0 | I5: 0 | J5: 1.2115916 | K5: 0 | L5: 0.017532974 | M5: 0 | N5: 0 | O5: 0 | P5: 0 | Q5: 0 | R5: 0 | S5: 0 | T5: 18.405805 | U5: 0.25796459 | V5: -0.093143005 | W5: =+SUM(B5:V5) -> 35.052362 | Y5: =+U5/U23+V5/U23 -> 0.0067654566 | Z5: =+(U5+V5)/$U$23 -> 0.0067654566
A6: Prod manu | B6: 6.9137748 | C6: 22.115421 | D6: 11.39659 | E6: 0 | F6: 0 | G6: 0 | H6: 0 | I6: 0 | J6: 23.089911 | K6: 0 | L6: 0.083720262 | M6: 0 | N6: 0 | O6: 0 | P6: 0 | Q6: 0 | R6: 0 | S6: 0 | T6: 13.489883 | U6: 19.344119 | V6: 1.2685029 | W6: =+SUM(B6:V6) -> 97.701922 | Z6: =+(U6+V6)/$U$23 -> 0.84608945
A7: Prod serv | B7: 4.4456911 | C7: 10.255334 | D7: 25.790392 | E7: 0 | F7: 0 | G7: 0 | H7: 0 | I7: 0 | J7: 32.838168 | K7: 0 | L7: 10.394112 | M7: 0 | N7: 0 | O7: 0 | P7: 0 | Q7: 0 | R7: 0 | S7: 0 | T7: 7.0574766 | U7: 3.5766315 | V7: 0.0081506483 | W7: =+SUM(B7:V7) -> 94.365956 | Z7: =+(U7+V7)/$U$23 -> 0.1471451
A8: Trabajo | B8: 2.9878269 | C8: 7.1010808 | D8: 24.044124 | E8: 0 | F8: 0 | G8: 0 | H8: 0 | I8: 0 | J8: 0 | K8: 0 | L8: 0 | M8: 0 | N8: 0 | O8: 0 | P8: 0 | Q8: 0 | R8: 0 | S8: 0 | T8: 0 | U8: 0 | V8: 0 | W8: =+SUM(B8:V8) -> 34.133031 | Y8: =+B8/(B8+B9) -> 0.18466653 | Z8: =+C8/(C8+C9) -> 0.37979709 | AA8: =+D8/(D8+D9) -> 0.4945751
A9: Capital | B9: 13.191753 | C9: 11.595958 | D9: 24.571594 | E9: 0 | F9: 0 | G9: 0 | H9: 0 | I9: 0 | J9: 0 | K9: 0 | L9: 0 | M9: 0 | N9: 0 | O9: 0 | P9: 0 | Q9: 0 | R9: 0 | S9: 0 | T9: 4.7540542 | U9: 0 | V9: 0 | W9: =+SUM(B9:V9) -> 54.113359 | Y9: =1-Y8 -> 0.81533347 | Z9: =1-Z8 -> 0.62020291 | AA9: =1-AA8 -> 0.5054249
A10: Hogares | B10: 0 | C10: 0 | D10: 0 | E10: 0 | F10: 0 | G10: 0 | H10: 34.131359 | I10: 12.060736 | J10: 0 | K10: 17.431284 | L10: 2.1073795 | M10: 0 | N10: 5.5067667 | O10: 0 | P10: 0 | Q10: 0 | R10: 0 | S10: 0 | T10: 0 | U10: 0 | V10: 0 | W10: =+SUM(B10:V10) -> 71.237526
A11: Empresas | B11: 0 | C11: 0 | D11: 0 | E11: 0 | F11: 0 | G11: 0 | H11: 0 | I11: 31.096709 | J11: 0 | K11: 0 | L11: 0 | M11: 5.8570051 | N11: 0 | O11: 0 | P11: 0 | Q11: 0 | R11: 0 | S11: 0 | T11: 0 | U11: 0 | V11: 0 | W11: =+SUM(B11:V11) -> 36.953715
A12: Gobierno | B12: 0 | C12: 0 | D12: 0 | E12: 0 | F12: 0 | G12: 0 | H12: 0 | I12: 0.9810935 | J12: 0 | K12: 0 | L12: 0 | M12: 1.6238783 | N12: 0 | O12: 5.8828657 | P12: 1.4448537 | Q12: 0.9510015 | R12: 7.3869769 | S12: 0.57276354 | T12: 0 | U12: 0 | V12: 0 | W12: =+SUM(B12:V12) -> 18.843433
A13: Cont_soc | B13: 0 | C13: 0 | D13: 0 | E13: 0 | F13: 0 | G13: 0 | H13: 0 | I13: 0 | J13: 7.4808834 | K13: 0 | L13: 0 | M13: 0 | N13: 0 | O13: 0 | P13: 0 | Q13: 0 | R13: 0 | S13: 0 | T13: 0 | U13: 0 | V13: 0 | W13: =+SUM(B13:V13) -> 7.4808834
A14: Pres_soc | B14: 0 | C14: 0 | D14: 0 | E14: 0 | F14: 0 | G14: 0 | H14: 0 | I14: 0 | J14: 0 | K14: 1.5233916 | L14: 3.9833751 | M14: 0 | N14: 0 | O14: 0 | P14: 0 | Q14: 0 | R14: 0 | S14: 0 | T14: 0 | U14: 0 | V14: 0 | W14: =+SUM(B14:V14) -> 5.5067667
A15: Imp_dir | B15: 0 | C15: 0 | D15: 0 | E15: 0 | F15: 0 | G15: 0 | H15: 0 | I15: 0 | J15: 1.208967 | K15: 4.6738987 | L15: 0 | M15: 0 | N15: 0 | O15: 0 | P15: 0 | Q15: 0 | R15: 0 | S15: 0 | T15: 0 | U15: 0 | V15: 0 | W15: =+SUM(B15:V15) -> 5.8828657
A16: Imp_prod | B16: 0.10199653 | C16: 0.24861445 | D16: 1.0942427 | E16: 0 | F16: 0 | G16: 0 | H16: 0 | I16: 0 | J16: 0 | K16: 0 | L16: 0 | M16: 0 | N16: 0 | O16: 0 | P16: 0 | Q16: 0 | R16: 0 | S16: 0 | T16: 0 | U16: 0 | V16: 0 | W16: =+SUM(B16:V16) -> 1.4448537
A17: Imptos_Espec | B17: 0 | C17: 0.9510015 | D17: 0 | E17: 0 | F17: 0 | G17: 0 | H17: 0 | I17: 0 | J17: 0 | K17: 0 | L17: 0 | M17: 0 | N17: 0 | O17: 0 | P17: 0 | Q17: 0 | R17: 0 | S17: 0 | T17: 0 | U17: 0 | V17: 0 | W17: =+SUM(B17:V17) -> 0.9510015
A18: IVA | B18: 0.012733687 | C18: 0.020328661 | D18: 1.4867791 | E18: 0.25476587 | F18: 5.033784 | G18: 0.57858551 | H18: 0 | I18: 0 | J18: 0 | K18: 0 | L18: 0 | M18: 0 | N18: 0 | O18: 0 | P18: 0 | Q18: 0 | R18: 0 | S18: 0 | T18: 0 | U18: 0 | V18: 0 | W18: =+SUM(B18:V18) -> 7.3869769
A19: Arancel | B19: 0 | C19: 0 | D19: 0 | E19: 0.079138214 | F19: 0.49359016 | G19: 3.5171018e-05 | H19: 0 | I19: 0 | J19: 0 | K19: 0 | L19: 0 | M19: 0 | N19: 0 | O19: 0 | P19: 0 | Q19: 0 | R19: 0 | S19: 0 | T19: 0 | U19: 0 | V19: 0 | W19: =+SUM(B19:V19) -> 0.57276354
A20: row | B20: 0 | C20: 0 | D20: 0 | E20: 5.7418532 | F20: 26.885652 | G20: 4.4749894 | H20: 0.00167188 | I20: 9.9748206 | J20: 0 | K20: 0 | L20: 0 | M20: 0 | N20: 0 | O20: 0 | P20: 0 | Q20: 0 | R20: 0 | S20: 0 | T20: 0 | U20: 0 | V20: 0 | W20: =+SUM(B20:V20) -> 47.078987
A21: S-I | B21: 0 | C21: 0 | D21: 0 | E21: 0 | F21: 0 | G21: 0 | H21: 0 | I21: 0 | J21: 5.4080054 | K21: 13.32514 | L21: 2.257313 | M21: 0 | N21: 0 | O21: 0 | P21: 0 | Q21: 0 | R21: 0 | S21: 0 | T21: 3.3717677 | U21: 0 | V21: 0 | W21: =+SUM(B21:V21) -> 24.362226
A22: Var_Exis | B22: 0 | C22: 0 | D22: 0 | E22: 0 | F22: 0 | G22: 0 | H22: 0 | I22: 0 | J22: 0 | K22: 0 | L22: 0 | M22: 0 | N22: 0 | O22: 0 | P22: 0 | Q22: 0 | R22: 0 | S22: 0 | T22: 0 | U22: 1.1835105 | V22: 0 | W22: =+SUM(B22:V22) -> 1.1835105
A23: Total | B23: =+SUM(B2:B22) -> 30.814314 | C23: =+SUM(C2:C22) -> 64.215722 | D23: =+SUM(D2:D22) -> 88.54781 | E23: =+SUM(E2:E22) -> 35.052362 | F23: =+SUM(F2:F22) -> 97.701922 | G23: =+SUM(G2:G22) -> 94.365955 | H23: =+SUM(H2:H22) -> 34.133031 | I23: =+SUM(I2:I22) -> 54.113359 | ... V23: =+SUM(V2:V22) -> 1.1835105 | W23: 0
B25: {=TRANSPOSE(W2:W22)} -> 30.814314 | C25: 64.215722 | D25: 88.54781 | E25: 35.052362 | F25: 97.701922 | G25: 94.365956 | H25: 34.133031 | I25: 54.113359 | J25: 71.237526 | K25: 36.953715 | L25: 18.843433 | M25: 7.4808834 | N25: 5.5067667 | O25: 5.8828657 | P25: 1.4448537 | Q25: 0.9510015 | R25: 7.3869769 | S25: 0.57276354 | T25: 47.078987 | U25: 24.362226 | V25: 1.1835105
B27: =ROUND(B23-B25,1) -> 0 | C27: =ROUND(C23-C25,1) -> 0 | D27: =ROUND(D23-D25,1) -> 0 | E27: =ROUND(E23-E25,1) -> 0 | F27: =ROUND(F23-F25,1) -> 0 | G27: =ROUND(G23-G25,1) -> 0 | H27: =ROUND(H23-H25,1) -> 0 | I27: =ROUND(I23-I25,1) -> 0 | ... V27: =ROUND(V23-V25,1) -> 0
E29: =+SUM(E2:E4) -> 28.976605 | F29: =+SUM(F2:F4) -> 65.288896 | G29: =+SUM(G2:G4) -> 89.312345 | I29: L prim | J29: L manu | K29: l serv | P29: Prod prim | Q29: Prod manu | R29: Prod serv
E30: =+E2/E$29 -> 0.99401014 | F30: =+F2/F$29 -> 0.016384471 | G30: =+G2/G$29 -> 0.010542218 | I30: =+$B$8*E30 -> 2.9699302 | J30: =+$C$8*F30 -> 0.11634745 | K30: =+$D$8*G30 -> 0.25347839 | N30: Act prim | O30: Prod prim | P30: =+E30*B5 -> 3.1416064 | Q30: =+E30*B6 -> 6.8723623 | R30: =+E30*B7 -> 4.4190621
E31: =+E3/E$29 -> 0.0059898563 | F31: =+F3/F$29 -> 0.96071054 | G31: =+G3/G$29 -> 0.014761969 | I31: =+$B$8*E31 -> 0.017896654 | J31: =+$C$8*F31 -> 6.8220831 | K31: =+$D$8*G31 -> 0.35493862 | N31: Act prim | O31: Prod manu | P31: =+E31*B5 -> 0.018931166 | Q31: =+E31*B6 -> 0.041412517 | R31: =+E31*B7 -> 0.026629051
E32: =+E4/E$29 -> 0 | F32: =+F4/F$29 -> 0.022904992 | G32: =+G4/G$29 -> 0.97469581 | I32: =+$B$8*E32 -> 0 | J32: =+$C$8*F32 -> 0.1626502 | K32: =+$D$8*G32 -> 23.435707 | N32: Act prim | O32: Prod serv | P32: 0 | Q32: 0 | R32: 0
N33: Act manu | O33: Prod prim | P33: =+F30*C5 -> 0.19543371 | Q33: =+F30*C6 -> 0.36234948 | R33: =+F30*C7 -> 0.16802822
B34: bloques: | I34: K prim | J34: K manu | K34: K serv | N34: Act manu | O34: Prod manu | P34: =+F31*C5 -> 11.45934 | Q34: =+F31*C6 -> 21.246518 | R34: =+F31*C7 -> 9.8524073
B35: consumidor | E35: =+E18/(E23-E18) -> 0.0073213641 | F35: =+F18/(F23-F18) -> 0.054320547 | G35: =+G18/(G23-G18) -> 0.0061691197 | I35: =+$B$9*E30 -> 13.112736 | J35: =+$C$9*F30 -> 0.18999363 | K35: =+$D$9*G30 -> 0.2590391 | N35: Act manu | O35: Prod serv | P35: =+F32*C5 -> 0.27321038 | Q35: =+F32*C6 -> 0.50655354 | R35: =+F32*C7 -> 0.23489834
B36: produccion | I36: =+$B$9*E31 -> 0.079016704 | J36: =+$C$9*F31 -> 11.140359 | K36: =+$D$9*G31 -> 0.36272512 | N36: Act serv | O36: Prod prim | P36: =+G30*D5 -> 0.0017298618 | Q36: =+G30*D6 -> 0.12014533 | R36: =+G30*D7 -> 0.27188793
B37: producto | C37: domestico | D37: importado | E37: domestico(hogares, gob, ins) | G37: export | H37: intermedio | I37: =+$B$9*E32 -> 0 | J37: =+$C$9*F32 -> 0.26560532 | K37: =+$D$9*G32 -> 23.94983 | N37: Act serv | O37: Prod manu | P37: =+G31*D5 -> 0.0024222766 | Q37: =+G31*D6 -> 0.16823611 | R37: =+G31*D7 -> 0.38071697
B38: empresa | N38: Act serv | O38: Prod serv | P38: =+G32*D5 -> 0.15993685 | Q38: =+G32*D6 -> 11.108208 | R38: =+G32*D7 -> 25.137787
B39: gobierno
B40: inversión | H40: =+H23/(H23+I23) -> 0.38679238 | I40: =1-H40 -> 0.61320762 | L40: 28
B41: ROW | C41: importacion | D41: exportacione | L41: =+L40*0.8 -> 22.4 | N41: PROD<pi::PRODS>(X<pi,p,s>[]^beta_x<pi,p,s>) | R41: =+R23-SUM(B18:D18) -> 5.8671354
B42: mercado | L42: =+L41*0.94 -> 21.056
N43: insumo-producto-actividad
...
